Workbook

Sheet Intro
A2: Buyer Persona del Proyecto (nivel Project Finance Tokenizado)
A3: Elemento | B3: Descripción
A4: Rol | B4: Sponsor o SPV de constelación satelital IoT
A5: Objetivo | B5: Lanzamiento de 80 satélites IoT + estaciones terrenas (estimado realista 2,3 MUSD/unidad)
A6: Horizonte del proyecto | B6: 12 años (3 de gracia + 9 de repago)
A7: Necesidad de financiamiento | B7: USD 90 M (80 % deuda, 20 % equity). | C7: Deuda (80%) | D7: Equity (20%)
A8: Tipo de deuda | B8: Project Finance tokenizado con tres tramos: senior, mezzanine y subordinado. | C8: 72 | D8: =0.2*90 | E8: Estructura típica para infraestructura digital emergente
A9: Tipo de inversores | B9: Distribución equilibrada por riesgo y prelación
A10: 0.6 | B10: 1️⃣ Senior token holders | C10: Fondos institucionales conservadores (infra funds, aseguradoras). Buscan bajo riesgo, tasa base + 100 bps.
A11: 0.25 | B11: 2️⃣ Mezzanine token holders | C11: Fondos de deuda privada o family offices. Aceptan riesgo medio, tasa base + 350 bps.
A12: 0.15 | B12: 3️⃣ Subordinated token holders | C12: Inversores alternativos o cripto institucionales (DeFi RWA funds). Aceptan alta volatilidad, tasa base + 600 bps.
A13: Flujos esperados | B13: ARPU bajo pero crecimiento exponencial por adopción IoT (lag comercial).
A14: Riesgos clave | B14: Delay en lanzamiento, fallas satelitales, adopción lenta, inflación de costos de lanzamiento.
A15: Mitigadores | B15: DSRA (12 meses), MRA (50 % del RCAPEX futuro), seguros de lanzamiento, covenant de dividend lock-up DSCR<1.25.
A16: Tasa base (SOFR) | B16: 5.0 % | C16: Coherente con entorno USD actual
A17: Spreads por tramo | B17: Tipo tasa | C17: Spread
A18: Senior +1.0 % → 6.0 %; | B18: 0.05 | C18: 0.01 | D18: =B18+C18
A19: Mezz +3.5 % → 8.5 %; | B19: 0.05 | C19: 0.035 | D19: =B19+C19
A20: Sub +6 % → 11.0 % | B20: 0.05 | C20: 0.06 | D20: =B20+C20
A21: Amortización | B21: “Sculpted” para mantener DSCR ≈ 1.20 en senior | C21: “Sculpted” (año 5–12)
A22: Sculpted
A23: Grace period (anos, solo intereses) | B23: 4 | C23: Permite alcanzar flujo positivo | D23: Hasta estabilizar ingresos (fase de commissioning y ramp-up)
A24: Vida útil total del proyecto (anos) | B24: 15 | C24: Incluye reposición año 10–15
A27: WACD
A28: =(Intro!D18*'Debt Service'!C29+'Debt Service'!C30*Intro!D19+Intro!D20*'Debt Service'!C31)/Intro!C8 | B28: WACD 6–8 %
B29: Normal digital infra
A30: PLCR
A31: =PLCR!F19
A32: LLCR
A33: =PLCR!F21 | B33: 1.25 – 1.40
A35: IRR
A36: Senior
A37: =IRR!E21
A38: Mezz
A39: =IRR!F21
A40: Sub
A41: =IRR!G21
A46: Línea Temporal Financiera (“Cash Flow Timeline”)
A47: Fase | B47: Año | C47: Evento | D47: Desembolso / Flujo | E47: Observaciones
A48: I. Ingeniería y Manufactura | B48: 0–2 | C48: Producción 40 satélites | D48: -USD 90 M | E48: Deuda + Equity (Drawdwon 1)
...

Sheet CFADS
A2: Horizonte: 15 años | I2: CFADS = Revenue – OPEX – Maintenance – ΔWC – Tax – RCAPEX
A3: CAPEX total: 90 MUSD | B3: Año | C3: revenue_gross | D3: opex | E3: maintenance_opex | F3: working_cap_change | G3: tax_paid | H3: rcapex_amount | I3: CFADS
A4: Ramp-up: 3 años hasta punto de equilibrio (año 5) | B4: 1 | C4: 0 | D4: 0.6 | E4: 0 | F4: 0 | G4: 0 | H4: 0 | I4: =-0.6-H4 | J4: Fase 1: fabricación y despliegue (parcial)
A5: Margen operativo bruto (EBITDA/revenue): 45–50% en régimen | B5: 2 | C5: 0 | D5: 1.2 | E5: 0 | F5: 0 | G5: 0 | H5: 0 | I5: -1.2 | J5: Fase 2: commissioning
A6: RCAPEX: Reposición cada 5 años (~20–30 MUSD) | B6: 3 | C6: 3 | D6: 2.4 | E6: 0.1 | F6: 0.2 | G6: 0 | H6: 0 | I6: 0.3 | J6: Inicio servicio beta
A7: Impuesto efectivo: 25–30% | B7: 4 | C7: 10 | D7: 4.5 | E7: 0.2 | F7: 0.3 | G7: 0 | H7: 0 | I7: 5 | J7: Ingresos recurrentes crecen
A8: Δ Working Capital: 1–2% de revenue (en crecimiento) | B8: 5 | C8: 20 | D8: 6.5 | E8: 0.3 | F8: 0.5 | G8: 0.3 | H8: 0 | I8: 12.4 | J8: Break-even operativo
B9: 6 | C9: 28 | D9: 8.5 | E9: 0.4 | F9: 0.5 | G9: 0.6 | H9: 1.2 | I9: 16.8 | J9: Cobertura global completa
B10: 7 | C10: 34 | D10: 10 | E10: 0.5 | F10: 0.5 | G10: 0.9 | H10: 1.5 | I10: 20.6 | J10: Madurez operativa
B11: 8 | C11: 38 | D11: 11.5 | E11: 0.6 | F11: 0.6 | G11: 1.2 | H11: 1.65 | I11: 22.45 | J11: Margen máximo
B12: 9 | C12: 40 | D12: 12 | E12: 0.7 | F12: 0.6 | G12: 1.4 | H12: 1.7 | I12: 23.6 | J12: Estabilización de demanda
B13: 10 | C13: 38 | D13: 12 | E13: 1.2 | F13: 0.6 | G13: 1.4 | H13: 1.55 | I13: 21.25 | J13: Inicio fase reposiciones
B14: 11 | C14: 35 | D14: 11.5 | E14: 0.8 | F14: 0.5 | G14: 1.2 | H14: 3.4 | I14: 17.6 | J14: Saturación de mercado
B15: 12 | C15: 33 | D15: 11 | E15: 0.8 | F15: 0.4 | G15: 1.1 | H15: 2.25 | I15: 17.45 | J15: Fin del repago
B16: 13 | C16: 30 | D16: 10.5 | E16: 0.9 | F16: 0.3 | G16: 0.9 | H16: 2 | I16: 15.4 | J16: Fase madura (post-debt)
B17: 14 | C17: 27 | D17: 10 | E17: 0.8 | F17: 0.2 | G17: 0.8 | H17: 1.5 | I17: 13.7 | J17: Flujo equity
B18: 15 | C18: 24 | D18: 9.5 | E18: 0.6 | F18: 0.2 | G18: 0.7 | H18: 1.25 | I18: 11.75 | J18: Fin de ciclo económico
C19: 360 | I19: =SUM(I4:I18)

Sheet Debt Service
B2: Año | C2: CFADS (USD M) | D2: Int_Senior | E2: Amort_Senior | F2: Int_Mezz | G2: Amort_Mezz | H2: Int_Sub | I2: Amort_Sub | J2: Servicio de deuda total (USD M) | K2: DSCR | N2: Objetivo | O2: CFADS-Int Tot | P2: Amor Total | Q2: S | R2: M | S2: Sub
B3: 1 | C3: 1.8 | D3: 0 | E3: 1.0625 | F3: 0 | G3: 0.825 | H3: 0 | J3: =SUM(D3:I3) | K3: -0.11299435 | L3: CAPEX y ramp-up (sin ingresos) | N3: 1.2 | O3: =C3-(D3+F3+H3) | P3: 0 | Q3: =P3*0.7 | R3: =P3*0.23 | S3: =P3*0.07
B4: 2 | C4: 1.8 | D4: 0 | E4: 1.0625 | F4: 0 | G4: 0.825 | H4: 0 | J4: =SUM(D4:I4) | K4: -0.2259887 | L4: Fase preoperativa | N4: 1.2 | O4: =C4-(D4+F4+H4) | P4: =C4/'Params (waterfall only)'!$B$10-(D4+F4+H4) | Q4: =P4*0.7 | R4: =P4*0.23 | S4: =P4*0.07
B5: 3 | C5: 1.8 | D5: 0 | E5: 1.0625 | F5: 0 | G5: 0.825 | H5: 0 | J5: =SUM(D5:I5) | K5: 0.056497175 | L5: Primeros clientes IoT | N5: 1.2 | O5: =C5-(D5+F5+H5) | P5: =C5/'Params (waterfall only)'!$B$10-(D5+F5+H5) | Q5: =P5*0.7 | R5: =P5*0.23 | S5: =P5*0.07
B6: 4 | C6: 1.8 | D6: 0 | E6: 1.0625 | F6: 0 | G6: 0.825 | H6: 0 | J6: =SUM(D6:I6) | K6: 0.94161959 | L6: Near break-even, aún interest-only | M6: Inicio amortización (DSCR≈1) | N6: 1.2 | O6: =C6-(D6+F6+H6) | P6: =C6/'Params (waterfall only)'!$B$10-(D6+F6+H6) | Q6: =P6*0.7 | R6: =P6*0.23 | S6: =P6*0.07
B7: 5 | C7: 1.8 | D7: 2.7272727 | E7: 1.0625 | F7: 1.1363636 | G7: 0.825 | H7: 0.68181818 | J7: =SUM(D7:I7) | K7: 1.45 | L7: DSCR objetivo alcanzado | N7: 1.2 | O7: =C7-(D7+F7+H7) | P7: =C7/'Params (waterfall only)'!$B$10-(D7+F7+H7) | Q7: =P7*0.7 | R7: =P7*0.23 | S7: =P7*0.07
B8: 6 | C8: 1.6363636 | D8: 2.7272727 | E8: 0.96590909 | F8: 1.1363636 | G8: 0.75 | H8: 0.68181818 | J8: =SUM(D8:I8) | K8: 1.2 | L8: Cashflow estable | M8: Máximo DSCR operativo | N8: 1.2 | O8: =C8-(D8+F8+H8) | P8: =C8/'Params (waterfall only)'!$B$10-(D8+F8+H8) | Q8: =P8*0.7 | R8: =P8*0.23 | S8: =P8*0.07
B9: 7 | C9: 1.4727273 | D9: 2.7272727 | E9: 0.86931818 | F9: 1.1363636 | G9: 0.675 | H9: 0.68181818 | J9: =SUM(D9:I9) | K9: 1.2 | L9: Cobertura holgada | N9: 1.2 | O9: =C9-(D9+F9+H9) | P9: =C9/'Params (waterfall only)'!$B$10-(D9+F9+H9) | Q9: =P9*0.7 | R9: =P9*0.23 | S9: =P9*0.07
B10: 8 | C10: 1.3090909 | D10: 2.7272727 | E10: 0.77272727 | F10: 1.1363636 | G10: 0.6 | H10: 0.68181818 | J10: =SUM(D10:I10) | K10: 1.45 | N10: 1.2 | O10: =C10-(D10+F10+H10) | P10: =C10/'Params (waterfall only)'!$B$10-(D10+F10+H10) | Q10: =P10*0.7 | R10: =P10*0.23 | S10: =P10*0.07
B11: 9 | C11: 1.1454545 | D11: 2.7272727 | E11: 0.67613636 | F11: 1.1363636 | G11: 0.525 | H11: 0.68181818 | J11: =SUM(D11:I11) | K11: 1.2 | L11: DSCR mantiene holgura | N11: 1.2 | O11: =C11-(D11+F11+H11) | P11: =C11/'Params (waterfall only)'!$B$10-(D11+F11+H11) | Q11: =P11*0.7 | R11: =P11*0.23 | S11: =P11*0.07
B12: 10 | C12: 0.98181818 | D12: 2.7272727 | E12: 0.57954545 | F12: 1.1363636 | G12: 0.45 | H12: 0.68181818 | J12: =SUM(D12:I12) | K12: 1.2 | N12: 1.2 | O12: =C12-(D12+F12+H12) | P12: =C12/'Params (waterfall only)'!$B$10-(D12+F12+H12) | Q12: =P12*0.7 | R12: =P12*0.23 | S12: =P12*0.07
B13: 11 | C13: 0.81818182 | D13: 2.7272727 | E13: 0.48295455 | F13: 1.1363636 | G13: 0.375 | H13: 0.68181818 | J13: =SUM(D13:I13) | K13: 1.2 | L13: Últimos años de repago | N13: 1.2 | O13: =C13-(D13+F13+H13) | P13: =C13/'Params (waterfall only)'!$B$10-(D13+F13+H13) | Q13: =P13*0.7 | R13: =P13*0.23 | S13: =P13*0.07
B14: 12 | C14: 0.65454545 | D14: 2.7272727 | E14: 0.38636364 | F14: 1.1363636 | G14: 0.3 | H14: 0.68181818 | J14: =SUM(D14:I14) | K14: =C14/J14 | N14: 1.2
B15: 13 | C15: 0.49090909 | D15: 2.7272727 | E15: 0.28977273 | F15: 1.1363636 | G15: 0.225 | H15: 0.68181818 | J15: =SUM(D15:I15) | K15: =C15/J15 | L15: Fin del repago (sin saldos vivos) | M15: Free CF post-debt | N15: 1.2
B16: 14 | C16: 0.32727273 | D16: 2.7272727 | E16: 0.19318182 | F16: 1.1363636 | G16: 0.15 | H16: 0.68181818 | J16: =SUM(D16:I16) | K16: =C16/J16 | L16: Flujo equity neto | N16: 1.2
B17: 15 | C17: 0.16363636 | D17: 2.7272727 | E17: 0.096590909 | F17: 1.1363636 | G17: 0.075 | H17: 0.68181818 | J17: =SUM(D17:I17) | K17: =C17/J17 | L17: Reservas MRA / RCAPEX | N17: 1.2
C18: =SUM(C3:C17) | D18: =SUM(D3:D17) | E18: =SUM(E3:E17) | F18: =SUM(F3:F17) | G18: =SUM(G3:G17) | H18: =SUM(H3:H17) | I18: =SUM(I3:I17) | J18: =SUM(J3:J17) | K18: =AVERAGE(K3:K17)
Q23: 1️⃣ CFADS vs Servicio Total
Q25: Tipo: gráfico de líneas.
Q27: Eje X: años (1–15).
B28: Tramo | C28: Principal inicial (USD M) | D28: Tipo tasa | E28: Spread | F28: Amortización | G28: Grace | H28: Pagos | I28: Protección | J28: Comentario
B29: Senior | C29: =Intro!A10*Intro!C8 | D29: SOFR + 100 bps | E29: flotante | F29: sculpted | G29: 12 meses | H29: Se amortiza de forma sculpted (ligada a CFADS), comenzando tras el grace. | I29: DSRA cubre 12 meses de deuda. | J29: Base SOFR + 100 bps. | Q29: Ejes Y: montos en millones USD.
B30: Mezzanine | C30: =Intro!A11*Intro!C8 | D30: SOFR + 300 bps | E30: flotante | F30: level payment | G30: 12 meses | H30: Pagos level payment, más lentos. | I30: No tiene DSRA directo, subordinado al senior. | J30: SOFR + 300 bps.
B31: Subordinated (Token) | C31: =Intro!C8*Intro!A12 | D31: Fixed (USDC) + 600 bps | E31: bullet | F31: 24 meses | H31: Solo paga intereses periódicos. | I31: Recupera capital al final (bullet). | J31: TOKEN_USDC + 600 bps. | Q31: Serie 1 (azul): CFADS.
Q33: Serie 2 (roja): Servicio_Total.
B34: Años 1–4: gracia total, intereses-only. DSCR < 1 → cubierto con equity + DSRA.
B35: Años 5–12: amortización escalonada (“sculpted”) → DSCR promedio ≈ 1.6×, mínimo 1.0×. | Q35: Interpretación:
B36: Años 13–15: deuda cancelada, flujos a equity (potencial para dividendos o MRA). | Q36: Muestra la cobertura de deuda año a año; cuando CFADS > Servicio, el excedente puede ir a MRA/DSRA o dividendos.
B38: Perfil típico de PF: “U” invertida — deuda se paga cuando CFADS crece y se estabiliza.
B39: Reserva de Servicio de Deuda (DSRA): equivalente a 12 meses de servicio senior ≈ 10–12 MUSD, cubre riesgo de brechas en los primeros años.
B40: Maintenance Reserve Account (MRA): acumula desde año 9 para RCAPEX (no afecta DSCR).
Q41: 2️⃣ DSCR vs Umbral Objetivo
Q43: Tipo: gráfico de líneas.
Q45: Serie 1: DSCR.
Q47: Serie 2 (línea discontinua): línea constante en 1.43×.
B49: 3️⃣ Saldos de Deuda por Tramo (área apilada) | Q49: Eje Y: ratio (sin unidades).
B51: Serie 1 (azul): saldo Senior. | Q51: Interpretación:
Q52: Permite ver visualmente el cumplimiento de covenants y períodos de lock-up.
B53: Serie 2 (naranja): saldo Mezzanine. | Q53: Los años con DSCR < 1.25 activarían el bloqueo de dividendos.
B55: Serie 3 (gris): saldo Subordinado.
...

Sheet PLCR
C2: Año | D2: CFADS (USD M) | E2: Factor descuento (1/(1+WACD)^t) | F2: Valor presente | I2: Métrica | J2: Valor calculado | K2: Fórmula / Definición | L2: Interpretación
C3: 1 | D3: =CFADS!I4 | E3: =1/((1+Intro!$A$28)^C3) | F3: =D3*E3 | I3: DSCR medio (años 5–12) | J3: 1.60× | K3: promedio CFADS / servicio total | L3: Nivel óptimo: >1.4× → proyecto bancable
C4: 2 | D4: =CFADS!I5 | E4: =1/((1+Intro!$A$28)^C4) | F4: =D4*E4 | I4: DSCR mínimo | J4: 1.00× | K4: año 5 (inicio repago) | L4: punto de control para DSRA
C5: 3 | D5: =CFADS!I6 | E5: =1/((1+Intro!$A$28)^C5) | F5: =D5*E5 | I5: LLCR (Loan Life Coverage Ratio) | J5: 1.37× | K5: NPV(CFADS vida deuda) / Deuda viva al inicio repago | L5: Cobertura razonable para riesgo medio (fuente: Esty, Gatti)
C6: 4 | D6: =CFADS!I7 | E6: =1/((1+Intro!$A$28)^C6) | F6: =D6*E6 | I6: PLCR (Project Life Coverage Ratio) | J6: 1.42× | K6: NPV(CFADS 1–15) / Deuda total | L6: Margen de cobertura total del proyecto
C7: 5 | D7: =CFADS!I8 | E7: =1/((1+Intro!$A$28)^C7) | F7: =D7*E7 | I7: WACD (Weighted Avg. Cost of Debt) | J7: 7.6 % | K7: (∑ r_i × principal_i)/∑ principal | L7: Costo promedio ponderado de la deuda
C8: 6 | D8: =CFADS!I9 | E8: =1/((1+Intro!$A$28)^C8) | F8: =D8*E8
C9: 7 | D9: =CFADS!I10 | E9: =1/((1+Intro!$A$28)^C9) | F9: =D9*E9
C10: 8 | D10: =CFADS!I11 | E10: =1/((1+Intro!$A$28)^C10) | F10: =D10*E10 | I10: LLCR | J10: Interpretación
C11: 9 | D11: =CFADS!I12 | E11: =1/((1+Intro!$A$28)^C11) | F11: =D11*E11 | I11: > 1.40 | J11: Muy sólido — margen de seguridad robusto
C12: 10 | D12: =CFADS!I13 | E12: =1/((1+Intro!$A$28)^C12) | F12: =D12*E12 | I12: 1.25 – 1.40 | J12: Aceptable — bancable sin soporte adicional
C13: 11 | D13: =CFADS!I14 | E13: =1/((1+Intro!$A$28)^C13) | F13: =D13*E13 | I13: 1.10 – 1.25 | J13: Marginal — requiere DSRA o garantía parcial
C14: 12 | D14: =CFADS!I15 | E14: =1/((1+Intro!$A$28)^C14) | F14: =D14*E14 | I14: < 1.10 | J14: Riesgoso — no bancable (deuda sobredimensionada)
C15: 13 | D15: =CFADS!I16 | E15: =1/((1+Intro!$A$28)^C15) | F15: =D15*E15
C16: 14 | D16: =CFADS!I17 | E16: =1/((1+Intro!$A$28)^C16) | F16: =D16*E16
C17: 15 | D17: =CFADS!I18 | E17: =1/((1+Intro!$A$28)^C17) | F17: =D17*E17
E19: PLCR | F19: =SUM(F3:F17)/Intro!C8 | G19: PLCR ≥ 1.4× | H19: Conservador | I19: ✅ 1.42× | K19: DSRA = 12 meses servicio | L19: Estándar | M19: ✅ Incluido conceptualmente
K20: RCAPEX vía MRA | L20: Buenas prácticas | M20: ✅ Aplicado (no afecta CFADS)
E21: LLCR | F21: =SUM(F7:F15)/Intro!C8 | G21: LLCR ≥ 1.3× | H21: Bancable | I21: ✅ 1.37×
J25: En estructuras PF reales, los umbrales mínimos típicos:
J26: LLCR ≥ 1.20–1.30 para proyectos maduros (utilities, infra digital).
J27: PLCR ≥ 1.40–1.60 para confort de largo plazo.
B33: A) Palancas sobre CFADS (numerador)
B34: Más ingresos: contratos ancla, take-or-pay/capacity commitments, pricing/ARPU mejor, o mayor penetración/volumen (ojo consistencia con buyer persona y competencia).
B35: Menos OPEX/maintenance: eficiencias TT&C/energía/seguros; calendarizar mejor RCAPEX para no concentrarlo en años críticos. | H35: “El LLCR y PLCR calculados sobre el flujo base muestran una cobertura inferior a 1×, evidenciando la necesidad de ajustar la estructura (ya sea por incremento del equity inicial, extensión de tenor o reducción del WACD mediante spreads más competitivos). En términos de pricing, el bajo LLCR explica spreads elevados (300–600 bps) requeridos por los inversores mezzanine y subordinados para alcanzar el EL y CVaR target.”
B36: Hedging de tasas/energía (cap/floor) para reducir volatilidad negativa del CFADS y mejorar cobertura promedio (indirecto sobre LLCR/PLCR vía estabilidad).
B39: B) Palancas sobre tasa/discount rate (r del NPV)
B40: Bajar WACD/costo de deuda:
B41: reducir spreads (mejoras de estructura, garantías, liquidez tokenizada, ECA/MLA, etc.);
B42: aumentar calidad/tenor de contratos;
B43: colateral híbrido (activos + reservas on-chain) que reduzca PD/LGD percibida.
B44: Menor r ⇒ mayor PV de CFADS ⇒ suben LLCR/PLCR.
B47: C) Palancas sobre perfil de deuda (denominador y servicio)
B48: Más equity / menos deuda al cierre (subí el equity del 30 % a 35–40 % o baja el monto de deuda): baja el denominador.
B49: Tenor más largo o amortización “sculpted” para alinear servicio con ramp-up: reduce presión temprana y aumenta ventana de flujos que entran al NPV del LLCR.
B50: Grace más largo (interest-only) si el ramp-up es más lento; mejora DSCR inicial y evita draw de reservas (no cambia LLCR directamente pero te permite sostener estructura que sí lo mejora).
B51: Refinanciación “mini-perm” (si esperás que el proyecto sea más bancable con históricos): primer tramo corto, luego refi con mejores términos; sube LLCR ex-ante si el r esperado de refi es menor.
... B57: Colateral digital (escrow en stablecoins, oráculos auditables) que reduce riesgo operativo de pagos. Todo esto empuja r a la baja, mejorando LLCR/PLCR.

Sheet Sculpted_Waterfall
A1: Año | B1: BOP_Senior | C1: BOP_Mezz | D1: BOP_Sub | E1: Int_Senior | F1: Int_Mezz | G1: Int_Sub | H1: S_star | I1: Atot | J1: Amort_Senior_base | K1: Amort_Mezz_base | L1: Amort_Sub_base | M1: Leftover1 | N1: Add_Senior | O1: Leftover2 | P1: Add_Mezz | Q1: Leftover3 | R1: Add_Sub | S1: Amort_Senior | T1: Amort_Mezz | U1: Amort_Sub | V1: EOP_Senior | W1: EOP_Mezz | X1: EOP_Sub | Y1: Service | Z1: DSCR | AA1: Extra_Capacity | AB1: Extra_S | AC1: Extra_M | AD1: Extra_U | AE1: DSRA_Funding | AF1: DSRA_Release | AG1: DSRA_Balance | AH1: MRA_Funding | AI1: MRA_Use | AJ1: MRA_Balance
A2: 1 | B2: =IF(A2=1, 'Params (waterfall only)'!$B$2, V1) | C2: =IF(A2=1, 'Params (waterfall only)'!$B$3, W1) | D2: =IF(A2=1, 'Params (waterfall only)'!$B$4, X1) | E2: =B2*'Params (waterfall only)'!$B$5 | F2: =C2*'Params (waterfall only)'!$B$6 | G2: =D2*'Params (waterfall only)'!$B$7 | H2: =IF(A2<='Params (waterfall only)'!$B$8, 0, MIN(CFADS!I4, CFADS!I4/'Params (waterfall only)'!$B$10)) | I2: =MAX(0, H2-(E2+F2+G2)) | J2: =MIN(B2, 'Params (waterfall only)'!$B$11*I2) | K2: =MIN(C2, 'Params (waterfall only)'!$B$12*I2) | L2: =MIN(D2, 'Params (waterfall only)'!$B$13*I2) | M2: =I2-(J2+K2+L2) | N2: =MAX(0, MIN(B2-J2, M2)) | O2: =MAX(0, M2-N2) | P2: =MAX(0, MIN(C2-K2, O2)) | Q2: =MAX(0, O2-P2) | R2: =MAX(0, MIN(D2-L2, Q2)) | S2: =IF(A2<='Params (waterfall only)'!$B$8,0, J2+N2) | T2: =IF(A2<='Params (waterfall only)'!$B$8,0, K2+P2) | U2: =IF(A2<='Params (waterfall only)'!$B$8,0, L2+R2) | V2: =MAX(0, B2-S2) | W2: =MAX(0, C2-T2) | X2: =MAX(0, D2-U2) | Y2: =E2+F2+G2+S2+T2+U2 | Z2: -0.11299435 | AA2: =MAX(0, CFADS!I4 - Y2) | AB2: =0 | AC2: =0 | AD2: =0 | AE2: -18 | AF2: 5.91 | AG2: 12 | AH2: 0 | AI2: 0 | AJ2: 0
A3: 2 | B3: =IF(A3=1, 'Params (waterfall only)'!$B$2, V2) | C3: =IF(A3=1, 'Params (waterfall only)'!$B$3, W2) | D3: =IF(A3=1, 'Params (waterfall only)'!$B$4, X2) | E3: =B3*'Params (waterfall only)'!$B$5 | F3: =C3*'Params (waterfall only)'!$B$6 | G3: =D3*'Params (waterfall only)'!$B$7 | H3: =IF(A3<='Params (waterfall only)'!$B$8, 0, MIN(CFADS!I5, CFADS!I5/'Params (waterfall only)'!$B$10)) | I3: =MAX(0, H3-(E3+F3+G3)) | J3: =MIN(B3, 'Params (waterfall only)'!$B$11*I3) | K3: =MIN(C3, 'Params (waterfall only)'!$B$12*I3) | L3: =MIN(D3, 'Params (waterfall only)'!$B$13*I3) | M3: =I3-(J3+K3+L3) | N3: =MAX(0, MIN(B3-J3, M3)) | O3: =MAX(0, M3-N3) | P3: =MAX(0, MIN(C3-K3, O3)) | Q3: =MAX(0, O3-P3) | R3: =MAX(0, MIN(D3-L3, Q3)) | S3: =IF(A3<='Params (waterfall only)'!$B$8,0, J3+N3) | T3: =IF(A3<='Params (waterfall only)'!$B$8,0, K3+P3) | U3: =IF(A3<='Params (waterfall only)'!$B$8,0, L3+R3) | V3: =MAX(0, B3-S3) | W3: =MAX(0, C3-T3) | X3: =MAX(0, D3-U3) | Y3: =E3+F3+G3+S3+T3+U3 | Z3: -0.2259887 | AA3: =MAX(0, CFADS!I5 - Y3) | AB3: =0 | AC3: =0 | AD3: =0 | AE3: 0 | AF3: 6.51 | AG3: 6.69 | AH3: 0 | AI3: 0 | AJ3: 0
A4: 3 | B4: =IF(A4=1, 'Params (waterfall only)'!$B$2, V3) | C4: =IF(A4=1, 'Params (waterfall only)'!$B$3, W3) | D4: =IF(A4=1, 'Params (waterfall only)'!$B$4, X3) | E4: =B4*'Params (waterfall only)'!$B$5 | F4: =C4*'Params (waterfall only)'!$B$6 | G4: =D4*'Params (waterfall only)'!$B$7 | H4: =IF(A4<='Params (waterfall only)'!$B$8, 0, MIN(CFADS!I6, CFADS!I6/'Params (waterfall only)'!$B$10)) | I4: =MAX(0, H4-(E4+F4+G4)) | J4: =MIN(B4, 'Params (waterfall only)'!$B$11*I4) | K4: =MIN(C4, 'Params (waterfall only)'!$B$12*I4) | L4: =MIN(D4, 'Params (waterfall only)'!$B$13*I4) | M4: =I4-(J4+K4+L4) | N4: =MAX(0, MIN(B4-J4, M4)) | O4: =MAX(0, M4-N4) | P4: =MAX(0, MIN(C4-K4, O4)) | Q4: =MAX(0, O4-P4) | R4: =MAX(0, MIN(D4-L4, Q4)) | S4: =IF(A4<='Params (waterfall only)'!$B$8,0, J4+N4) | T4: =IF(A4<='Params (waterfall only)'!$B$8,0, K4+P4) | U4: =IF(A4<='Params (waterfall only)'!$B$8,0, L4+R4) | V4: =MAX(0, B4-S4) | W4: =MAX(0, C4-T4) | X4: =MAX(0, D4-U4) | Y4: =E4+F4+G4+S4+T4+U4 | Z4: 0.056497175 | AA4: =MAX(0, CFADS!I6 - Y4) | AB4: =0 | AC4: =0 | AD4: =0 | AE4: -3.63 | AF4: 5.01 | AG4: 5.31 | AH4: -0.14 | AI4: 0 | AJ4: 0.14
A5: 4 | B5: =IF(A5=1, 'Params (waterfall only)'!$B$2, V4) | C5: =IF(A5=1, 'Params (waterfall only)'!$B$3, W4) | D5: =IF(A5=1, 'Params (waterfall only)'!$B$4, X4) | E5: =B5*'Params (waterfall only)'!$B$5 | F5: =C5*'Params (waterfall only)'!$B$6 | G5: =D5*'Params (waterfall only)'!$B$7 | H5: =IF(A5<='Params (waterfall only)'!$B$8, 0, MIN(CFADS!I7, CFADS!I7/'Params (waterfall only)'!$B$10)) | I5: =MAX(0, H5-(E5+F5+G5)) | J5: =MIN(B5, 'Params (waterfall only)'!$B$11*I5) | K5: =MIN(C5, 'Params (waterfall only)'!$B$12*I5) | L5: =MIN(D5, 'Params (waterfall only)'!$B$13*I5) | M5: =I5-(J5+K5+L5) | N5: =MAX(0, MIN(B5-J5, M5)) | O5: =MAX(0, M5-N5) | P5: =MAX(0, MIN(C5-K5, O5)) | Q5: =MAX(0, O5-P5) | R5: =MAX(0, MIN(D5-L5, Q5)) | S5: =IF(A5<='Params (waterfall only)'!$B$8,0, J5+N5) | T5: =IF(A5<='Params (waterfall only)'!$B$8,0, K5+P5) | U5: =IF(A5<='Params (waterfall only)'!$B$8,0, L5+R5) | V5: =MAX(0, B5-S5) | W5: =MAX(0, C5-T5) | X5: =MAX(0, D5-U5) | Y5: =E5+F5+G5+S5+T5+U5 | Z5: 0.94161959 | AA5: =MAX(0, CFADS!I7 - Y5) | AB5: =0 | AC5: =0 | AD5: =0 | AE5: -3.552 | AF5: 0.31 | AG5: 8.552 | AH5: -0.315 | AI5: 0 | AJ5: 0.455
A6: 5 | B6: =IF(A6=1, 'Params (waterfall only)'!$B$2, V5) | C6: =IF(A6=1, 'Params (waterfall only)'!$B$3, W5) | D6: =IF(A6=1, 'Params (waterfall only)'!$B$4, X5) | E6: =B6*'Params (waterfall only)'!$B$5 | F6: =C6*'Params (waterfall only)'!$B$6 | G6: =D6*'Params (waterfall only)'!$B$7 | H6: =IF(A6<='Params (waterfall only)'!$B$8, 0, MIN(CFADS!I8, CFADS!I8/'Params (waterfall only)'!$B$10)) | I6: =MAX(0, H6-(E6+F6+G6)) | J6: =MIN(B6, 'Params (waterfall only)'!$B$11*I6) | K6: =MIN(C6, 'Params (waterfall only)'!$B$12*I6) | L6: =MIN(D6, 'Params (waterfall only)'!$B$13*I6) | M6: =I6-(J6+K6+L6) | N6: =MAX(0, MIN(B6-J6, M6)) | O6: =MAX(0, M6-N6) | P6: =MAX(0, MIN(C6-K6, O6)) | Q6: =MAX(0, O6-P6) | R6: =MAX(0, MIN(D6-L6, Q6)) | S6: =IF(A6<='Params (waterfall only)'!$B$8,0, J6+N6) | T6: =IF(A6<='Params (waterfall only)'!$B$8,0, K6+P6) | U6: =IF(A6<='Params (waterfall only)'!$B$8,0, L6+R6) | V6: =MAX(0, B6-S6) | W6: =MAX(0, C6-T6) | X6: =MAX(0, D6-U6) | Y6: =E6+F6+G6+S6+T6+U6 | Z6: 1.45 | AA6: =MAX(0, CFADS!I8 - Y6) | AB6: =0 | AC6: =0 | AD6: =0 | AE6: -3.862 | AF6: 0 | AG6: 12.414 | AH6: -0.5075 | AI6: 0 | AJ6: 0.9625
A7: 6 | B7: =IF(A7=1, 'Params (waterfall only)'!$B$2, V6) | C7: =IF(A7=1, 'Params (waterfall only)'!$B$3, W6) | D7: =IF(A7=1, 'Params (waterfall only)'!$B$4, X6) | E7: =B7*'Params (waterfall only)'!$B$5 | F7: =C7*'Params (waterfall only)'!$B$6 | G7: =D7*'Params (waterfall only)'!$B$7 | H7: =IF(A7<='Params (waterfall only)'!$B$8, 0, MIN(CFADS!I9, CFADS!I9/'Params (waterfall only)'!$B$10)) | I7: =MAX(0, H7-(E7+F7+G7)) | J7: =MIN(B7, 'Params (waterfall only)'!$B$11*I7) | K7: =MIN(C7, 'Params (waterfall only)'!$B$12*I7) | L7: =MIN(D7, 'Params (waterfall only)'!$B$13*I7) | M7: =I7-(J7+K7+L7) | N7: =MAX(0, MIN(B7-J7, M7)) | O7: =MAX(0, M7-N7) | P7: =MAX(0, MIN(C7-K7, O7)) | Q7: =MAX(0, O7-P7) | R7: =MAX(0, MIN(D7-L7, Q7)) | S7: =IF(A7<='Params (waterfall only)'!$B$8,0, J7+N7) | T7: =IF(A7<='Params (waterfall only)'!$B$8,0, K7+P7) | U7: =IF(A7<='Params (waterfall only)'!$B$8,0, L7+R7) | V7: =MAX(0, B7-S7) | W7: =MAX(0, C7-T7) | X7: =MAX(0, D7-U7) | Y7: =E7+F7+G7+S7+T7+U7 | Z7: 1.2 | AA7: =MAX(0, CFADS!I9 - Y7) | AB7: =0 | AC7: =0 | AD7: =0 | AE7: -15.241 | AF7: 12.414 | AG7: 15.241 | AH7: -0.565833 | AI7: 0.42 | AJ7: 1.108333
A8: 7 | B8: =IF(A8=1, 'Params (waterfall only)'!$B$2, V7) | C8: =IF(A8=1, 'Params (waterfall only)'!$B$3, W7) | D8: =IF(A8=1, 'Params (waterfall only)'!$B$4, X7) | E8: =B8*'Params (waterfall only)'!$B$5 | F8: =C8*'Params (waterfall only)'!$B$6 | G8: =D8*'Params (waterfall only)'!$B$7 | H8: =IF(A8<='Params (waterfall only)'!$B$8, 0, MIN(CFADS!I10, CFADS!I10/'Params (waterfall only)'!$B$10)) | I8: =MAX(0, H8-(E8+F8+G8)) | J8: =MIN(B8, 'Params (waterfall only)'!$B$11*I8) | K8: =MIN(C8, 'Params (waterfall only)'!$B$12*I8) | L8: =MIN(D8, 'Params (waterfall only)'!$B$13*I8) | M8: =I8-(J8+K8+L8) | N8: =MAX(0, MIN(B8-J8, M8)) | O8: =MAX(0, M8-N8) | P8: =MAX(0, MIN(C8-K8, O8)) | Q8: =MAX(0, O8-P8) | R8: =MAX(0, MIN(D8-L8, Q8)) | S8: =IF(A8<='Params (waterfall only)'!$B$8,0, J8+N8) | T8: =IF(A8<='Params (waterfall only)'!$B$8,0, K8+P8) | U8: =IF(A8<='Params (waterfall only)'!$B$8,0, L8+R8) | V8: =MAX(0, B8-S8) | W8: =MAX(0, C8-T8) | X8: =MAX(0, D8-U8) | Y8: =E8+F8+G8+S8+T8+U8 | Z8: 1.2 | AA8: =MAX(0, CFADS!I10 - Y8) | AB8: =0 | AC8: =0 | AD8: =0 | AE8: -1.379 | AF8: 0 | AG8: 16.621 | AH8: -0.571667 | AI8: 0.525 | AJ8: 1.155
A9: 8 | B9: =IF(A9=1, 'Params (waterfall only)'!$B$2, V8) | C9: =IF(A9=1, 'Params (waterfall only)'!$B$3, W8) | D9: =IF(A9=1, 'Params (waterfall only)'!$B$4, X8) | E9: =B9*'Params (waterfall only)'!$B$5 | F9: =C9*'Params (waterfall only)'!$B$6 | G9: =D9*'Params (waterfall only)'!$B$7 | H9: =IF(A9<='Params (waterfall only)'!$B$8, 0, MIN(CFADS!I11, CFADS!I11/'Params (waterfall only)'!$B$10)) | I9: =MAX(0, H9-(E9+F9+G9)) | J9: =MIN(B9, 'Params (waterfall only)'!$B$11*I9) | K9: =MIN(C9, 'Params (waterfall only)'!$B$12*I9) | L9: =MIN(D9, 'Params (waterfall only)'!$B$13*I9) | M9: =I9-(J9+K9+L9) | N9: =MAX(0, MIN(B9-J9, M9)) | O9: =MAX(0, M9-N9) | P9: =MAX(0, MIN(C9-K9, O9)) | Q9: =MAX(0, O9-P9) | R9: =MAX(0, MIN(D9-L9, Q9)) | S9: =IF(A9<='Params (waterfall only)'!$B$8,0, J9+N9) | T9: =IF(A9<='Params (waterfall only)'!$B$8,0, K9+P9) | U9: =IF(A9<='Params (waterfall only)'!$B$8,0, L9+R9) | V9: =MAX(0, B9-S9) | W9: =MAX(0, C9-T9) | X9: =MAX(0, D9-U9) | Y9: =E9+F9+G9+S9+T9+U9 | Z9: 1.45 | AA9: =MAX(0, CFADS!I11 - Y9) | AB9: =0 | AC9: =0 | AD9: =0 | AE9: -0.828 | AF9: 0 | AG9: 17.448 | AH9: -0.775833 | AI9: 0.5775 | AJ9: 1.353333
A10: 9 | B10: =IF(A10=1, 'Params (waterfall only)'!$B$2, V9) | C10: =IF(A10=1, 'Params (waterfall only)'!$B$3, W9) | D10: =IF(A10=1, 'Params (waterfall only)'!$B$4, X9) | E10: =B10*'Params (waterfall only)'!$B$5 | F10: =C10*'Params (waterfall only)'!$B$6 | G10: =D10*'Params (waterfall only)'!$B$7 | H10: =IF(A10<='Params (waterfall only)'!$B$8, 0, MIN(CFADS!I12, CFADS!I12/'Params (waterfall only)'!$B$10)) | I10: =MAX(0, H10-(E10+F10+G10)) | J10: =MIN(B10, 'Params (waterfall only)'!$B$11*I10) | K10: =MIN(C10, 'Params (waterfall only)'!$B$12*I10) | L10: =MIN(D10, 'Params (waterfall only)'!$B$13*I10) | M10: =I10-(J10+K10+L10) | N10: =MAX(0, MIN(B10-J10, M10)) | O10: =MAX(0, M10-N10) | P10: =MAX(0, MIN(C10-K10, O10)) | Q10: =MAX(0, O10-P10) | R10: =MAX(0, MIN(D10-L10, Q10)) | S10: =IF(A10<='Params (waterfall only)'!$B$8,0, J10+N10) | T10: =IF(A10<='Params (waterfall only)'!$B$8,0, K10+P10) | U10: =IF(A10<='Params (waterfall only)'!$B$8,0, L10+R10) | V10: =MAX(0, B10-S10) | W10: =MAX(0, C10-T10) | X10: =MAX(0, D10-U10) | Y10: =E10+F10+G10+S10+T10+U10 | Z10: 1.2 | AA10: =MAX(0, CFADS!I12 - Y10) | AB10: =0 | AC10: =0 | AD10: =0 | AE10: 0 | AF10: 0 | AG10: 17.448 | AH10: -0.84 | AI10: 0.595 | AJ10: 1.598333
A11: 10 | B11: =IF(A11=1, 'Params (waterfall only)'!$B$2, V10) | C11: =IF(A11=1, 'Params (waterfall only)'!$B$3, W10) | D11: =IF(A11=1, 'Params (waterfall only)'!$B$4, X10) | E11: =B11*'Params (waterfall only)'!$B$5 | F11: =C11*'Params (waterfall only)'!$B$6 | G11: =D11*'Params (waterfall only)'!$B$7 | H11: =IF(A11<='Params (waterfall only)'!$B$8, 0, MIN(CFADS!I13, CFADS!I13/'Params (waterfall only)'!$B$10)) | I11: =MAX(0, H11-(E11+F11+G11)) | J11: =MIN(B11, 'Params (waterfall only)'!$B$11*I11) | K11: =MIN(C11, 'Params (waterfall only)'!$B$12*I11) | L11: =MIN(D11, 'Params (waterfall only)'!$B$13*I11) | M11: =I11-(J11+K11+L11) | N11: =MAX(0, MIN(B11-J11, M11)) | O11: =MAX(0, M11-N11) | P11: =MAX(0, MIN(C11-K11, O11)) | Q11: =MAX(0, O11-P11) | R11: =MAX(0, MIN(D11-L11, Q11)) | S11: =IF(A11<='Params (waterfall only)'!$B$8,0, J11+N11) | T11: =IF(A11<='Params (waterfall only)'!$B$8,0, K11+P11) | U11: =IF(A11<='Params (waterfall only)'!$B$8,0, L11+R11) | V11: =MAX(0, B11-S11) | W11: =MAX(0, C11-T11) | X11: =MAX(0, D11-U11) | Y11: =E11+F11+G11+S11+T11+U11 | Z11: 1.2 | AA11: =MAX(0, CFADS!I13 - Y11) | AB11: =0 | AC11: =0 | AD11: =0 | AE11: -4.181 | AF11: 10.924 | AG11: 10.706 | AH11: -0.8925 | AI11: 0.5425 | AJ11: 1.948333
A12: 11 | B12: =IF(A12=1, 'Params (waterfall only)'!$B$2, V11) | C12: =IF(A12=1, 'Params (waterfall only)'!$B$3, W11) | D12: =IF(A12=1, 'Params (waterfall only)'!$B$4, X11) | E12: =B12*'Params (waterfall only)'!$B$5 | F12: =C12*'Params (waterfall only)'!$B$6 | G12: =D12*'Params (waterfall only)'!$B$7 | H12: =IF(A12<='Params (waterfall only)'!$B$8, 0, MIN(CFADS!I14, CFADS!I14/'Params (waterfall only)'!$B$10)) | I12: =MAX(0, H12-(E12+F12+G12)) | J12: =MIN(B12, 'Params (waterfall only)'!$B$11*I12) | K12: =MIN(C12, 'Params (waterfall only)'!$B$12*I12) | L12: =MIN(D12, 'Params (waterfall only)'!$B$13*I12) | M12: =I12-(J12+K12+L12) | N12: =MAX(0, MIN(B12-J12, M12)) | O12: =MAX(0, M12-N12) | P12: =MAX(0, MIN(C12-K12, O12)) | Q12: =MAX(0, O12-P12) | R12: =MAX(0, MIN(D12-L12, Q12)) | S12: =IF(A12<='Params (waterfall only)'!$B$8,0, J12+N12) | T12: =IF(A12<='Params (waterfall only)'!$B$8,0, K12+P12) | U12: =IF(A12<='Params (waterfall only)'!$B$8,0, L12+R12) | V12: =MAX(0, B12-S12) | W12: =MAX(0, C12-T12) | X12: =MAX(0, D12-U12) | Y12: =E12+F12+G12+S12+T12+U12 | Z12: 1.2 | AA12: =MAX(0, CFADS!I14 - Y12) | AB12: =0 | AC12: =0 | AD12: =0 | AE12: 0 | AF12: 0 | AG12: 10.706 | AH12: -0.670833 | AI12: 1.19 | AJ12: 1.429166
A13: 12 | B13: =IF(A13=1, 'Params (waterfall only)'!$B$2, V12) | C13: =IF(A13=1, 'Params (waterfall only)'!$B$3, W12) | D13: =IF(A13=1, 'Params (waterfall only)'!$B$4, X12) | E13: =B13*'Params (waterfall only)'!$B$5 | F13: =C13*'Params (waterfall only)'!$B$6 | G13: =D13*'Params (waterfall only)'!$B$7 | H13: =IF(A13<='Params (waterfall only)'!$B$8, 0, MIN(CFADS!I15, CFADS!I15/'Params (waterfall only)'!$B$10)) | I13: =MAX(0, H13-(E13+F13+G13)) | J13: =MIN(B13, 'Params (waterfall only)'!$B$11*I13) | K13: =MIN(C13, 'Params (waterfall only)'!$B$12*I13) | L13: =MIN(D13, 'Params (waterfall only)'!$B$13*I13) | M13: =I13-(J13+K13+L13) | N13: =MAX(0, MIN(B13-J13, M13)) | O13: =MAX(0, M13-N13) | P13: =MAX(0, MIN(C13-K13, O13)) | Q13: =MAX(0, O13-P13) | R13: =MAX(0, MIN(D13-L13, Q13)) | S13: =IF(A13<='Params (waterfall only)'!$B$8,0, J13+N13) | T13: =IF(A13<='Params (waterfall only)'!$B$8,0, K13+P13) | U13: =IF(A13<='Params (waterfall only)'!$B$8,0, L13+R13) | V13: =MAX(0, B13-S13) | W13: =MAX(0, C13-T13) | X13: =MAX(0, D13-U13) | Y13: =E13+F13+G13+S13+T13+U13 | Z13: =IF(Y13=0,"", CFADS!I15/Y13) | AA13: =MAX(0, CFADS!I15 - Y13) | AB13: =0 | AC13: =0 | AD13: =0 | AE13: 0 | AF13: 0 | AG13: 10.706 | AH13: -0.554167 | AI13: 0.7875 | AJ13: 1.195833
A14: 13 | B14: =IF(A14=1, 'Params (waterfall only)'!$B$2, V13) | C14: =IF(A14=1, 'Params (waterfall only)'!$B$3, W13) | D14: =IF(A14=1, 'Params (waterfall only)'!$B$4, X13) | E14: =B14*'Params (waterfall only)'!$B$5 | F14: =C14*'Params (waterfall only)'!$B$6 | G14: =D14*'Params (waterfall only)'!$B$7 | H14: =IF(A14<='Params (waterfall only)'!$B$8, 0, MIN(CFADS!I16, CFADS!I16/'Params (waterfall only)'!$B$10)) | I14: =MAX(0, H14-(E14+F14+G14)) | J14: =MIN(B14, 'Params (waterfall only)'!$B$11*I14) | K14: =MIN(C14, 'Params (waterfall only)'!$B$12*I14) | L14: =MIN(D14, 'Params (waterfall only)'!$B$13*I14) | M14: =I14-(J14+K14+L14) | N14: =MAX(0, MIN(B14-J14, M14)) | O14: =MAX(0, M14-N14) | P14: =MAX(0, MIN(C14-K14, O14)) | Q14: =MAX(0, O14-P14) | R14: =MAX(0, MIN(D14-L14, Q14)) | S14: =IF(A14<='Params (waterfall only)'!$B$8,0, J14+N14) | T14: =IF(A14<='Params (waterfall only)'!$B$8,0, K14+P14) | U14: =IF(A14<='Params (waterfall only)'!$B$8,0, L14+R14) | V14: =MAX(0, B14-S14) | W14: =MAX(0, C14-T14) | X14: =MAX(0, D14-U14) | Y14: =E14+F14+G14+S14+T14+U14 | Z14: =IF(Y14=0,"", CFADS!I16/Y14) | AA14: =MAX(0, CFADS!I16 - Y14) | AB14: =0 | AC14: =0 | AD14: =0 | AE14: 0 | AF14: 0 | AG14: 10.706 | AH14: -0.320833 | AI14: 0.7 | AJ14: 0.816666
A15: 14 | B15: =IF(A15=1, 'Params (waterfall only)'!$B$2, V14) | C15: =IF(A15=1, 'Params (waterfall only)'!$B$3, W14) | D15: =IF(A15=1, 'Params (waterfall only)'!$B$4, X14) | E15: =B15*'Params (waterfall only)'!$B$5 | F15: =C15*'Params (waterfall only)'!$B$6 | G15: =D15*'Params (waterfall only)'!$B$7 | H15: =IF(A15<='Params (waterfall only)'!$B$8, 0, MIN(CFADS!I17, CFADS!I17/'Params (waterfall only)'!$B$10)) | I15: =MAX(0, H15-(E15+F15+G15)) | J15: =MIN(B15, 'Params (waterfall only)'!$B$11*I15) | K15: =MIN(C15, 'Params (waterfall only)'!$B$12*I15) | L15: =MIN(D15, 'Params (waterfall only)'!$B$13*I15) | M15: =I15-(J15+K15+L15) | N15: =MAX(0, MIN(B15-J15, M15)) | O15: =MAX(0, M15-N15) | P15: =MAX(0, MIN(C15-K15, O15)) | Q15: =MAX(0, O15-P15) | R15: =MAX(0, MIN(D15-L15, Q15)) | S15: =IF(A15<='Params (waterfall only)'!$B$8,0, J15+N15) | T15: =IF(A15<='Params (waterfall only)'!$B$8,0, K15+P15) | U15: =IF(A15<='Params (waterfall only)'!$B$8,0, L15+R15) | V15: =MAX(0, B15-S15) | W15: =MAX(0, C15-T15) | X15: =MAX(0, D15-U15) | Y15: =E15+F15+G15+S15+T15+U15 | Z15: =IF(Y15=0,"", CFADS!I17/Y15) | AA15: =MAX(0, CFADS!I17 - Y15) | AB15: =0 | AC15: =0 | AD15: =0 | AE15: 0 | AF15: 0 | AG15: 10.706 | AH15: -0.145833 | AI15: 0.525 | AJ15: 0.437499
A16: 15 | B16: =IF(A16=1, 'Params (waterfall only)'!$B$2, V15) | C16: =IF(A16=1, 'Params (waterfall only)'!$B$3, W15) | D16: =IF(A16=1, 'Params (waterfall only)'!$B$4, X15) | E16: =B16*'Params (waterfall only)'!$B$5 | F16: =C16*'Params (waterfall only)'!$B$6 | G16: =D16*'Params (waterfall only)'!$B$7 | H16: =IF(A16<='Params (waterfall only)'!$B$8, 0, MIN(CFADS!I18, CFADS!I18/'Params (waterfall only)'!$B$10)) | I16: =MAX(0, H16-(E16+F16+G16)) | J16: =MIN(B16, 'Params (waterfall only)'!$B$11*I16) | K16: =MIN(C16, 'Params (waterfall only)'!$B$12*I16) | L16: =MIN(D16, 'Params (waterfall only)'!$B$13*I16) | M16: =I16-(J16+K16+L16) | N16: =MAX(0, MIN(B16-J16, M16)) | O16: =MAX(0, M16-N16) | P16: =MAX(0, MIN(C16-K16, O16)) | Q16: =MAX(0, O16-P16) | R16: =MAX(0, MIN(D16-L16, Q16)) | S16: =IF(A16<='Params (waterfall only)'!$B$8,0, J16+N16) | T16: 0 | U16: =IF(A16<='Params (waterfall only)'!$B$8,0, L16+R16+AE16) | V16: =MAX(0, B16-S16) | W16: =MAX(0, C16-T16) | X16: =MAX(0, D16-U16) | Y16: =E16+F16+G16+S16+T16+U16 | Z16: =IF(Y16=0,"", CFADS!I18/Y16) | AA16: =MAX(0, CFADS!I18 - Y16) | AB16: =MIN(AB16, B16-S16) | AC16: =MIN(AB16-AC16, C16-T16) | AD16: =MIN(AB16-AC16-AD16, D16-U16) | AE16: 0 | AF16: 0 | AG16: 10.706 | AH16: 0 | AI16: 0.4375 | AJ16: -1e-06
E17: =SUM(E2:E16) | F17: =SUM(F2:F16) | G17: =SUM(G2:G16) | Y17: =SUM(Y2:Y16) | Z17: =AVERAGE(Z2:Z16)
J19: 📘 1. Estructura lógica del Waterfall (orden de prioridad)
J21: El Waterfall o “cash flow cascade” es una tabla de flujos ordenada según prelación de pagos.
J34: Orden | K34: Concepto | M34: Fórmula / Acción | R34: Resultado
J35: 1 | K35: CFADS | M35: Flujo operativo disponible para servicio de deuda | R35: Ingreso base del año
J36: 2 | K36: Pago intereses + amortizaciones (senior → mezz → sub) | M36: =MIN(CFADS + DSRA_draw, Servicio_Total) | R36: Si CFADS no alcanza, se usa DSRA
J37: 3 | K37: DSRA draw (si CFADS < servicio) | M37: =MIN(Faltante, DSRA_balance) | R37: Reduce DSRA
J38: 4 | K38: DSRA top-up (si sobran fondos y DSRA < target) | M38: =MIN(DSRA_target - DSRA_balance, Cash_remanente) | R38: Restaura DSRA
J39: 5 | K39: MRA use (si hay RCAPEX ese año) | M39: =MIN(RCAPEX_t, MRA_balance) | R39: Disminuye MRA
J40: 6 | K40: MRA top-up (si no se alcanzó target para próximo RCAPEX) | M40: =MIN(MRA_target - MRA_balance, Cash_remanente) | R40: Reconstituye MRA
J41: 7 | K41: Cash sweep / dividendos | M41: =MAX(0, Cash_remanente) | R41: Flujo residual a equity
J44: Años 1–4: DSRA cubre déficit (draw), CFADS negativo → DSRA baja.
J45: Años 5–6: CFADS supera servicio → se repone DSRA (top-up), se fondea MRA para RCAPEX futuro.
J46: Años 10 y 15: MRA se usa (MRA_use) para pagar el RCAPEX satelital (reposición).
J49: Tu tesis propone tokenizar los tramos de deuda (Senior / Mezz / Sub) pero mantener las cuentas de reserva (DSRA, MRA) como smart contracts custodiados:
J51: Elemento | K51: Off-chain equivalente | N51: On-chain implementación
J52: DSRA | K52: Escrow bancario a nombre del SPV | N52: Smart contract de custodia con lógica de top-up/draw
J53: MRA | K53: Cuenta restringida en proyecto | N53: Smart contract vinculado al calendario RCAPEX
J54: Dividend Lock-up | K54: Covenant contractual | N54: Condición automatizada (if DSCR < 1.25 then lock=true)
J55: Cash Sweep | K55: Obligación de prepago anticipado | N55: Smart function (if CFADS > target then sweep = %excedente)
J57: El flujo de caja del SPV (en USDC/fiat) puede representarse como tokens de entrada que recorren el waterfall en un árbol de distribución on-chain.
J58: Esa lógica es exactamente lo que tenés modelado en la pestaña Waterfall.

Sheet Params (waterfall only)
A1: Param | B1: Value
A2: Principal_Senior | B2: 30
A3: Principal_Mezz | B3: 12.5
A4: Principal_Sub | B4: 7.5
A5: Rate_Senior | B5: =Intro!D18
A6: Rate_Mezz | B6: =Intro!D19
A7: Rate_Sub | B7: =Intro!D20
A8: Grace_Years | B8: =Intro!B23
A9: Tenor_Years | B9: =Intro!B24
A10: DSCR_Obj | B10: 1.2
A11: Weight_Senior | B11: 0.6
A12: Weight_Mezz | B12: 0.25
A13: Weight_Sub | B13: 0.15
A14: DSRA_initial | B14: 8.3333333

Sheet IRR
D3: Año | E3: Flujo Senior | F3: Flujo Mezz | G3: Flujo Sub | I3: Tramo | J3: Inversión inicial (MUSD) | K3: Promedio de cobros anuales (MUSD) | L3: TIR nominal anual estimada | M3: Rango típico PF (benchmark)
D4: 0 | E4: =-'Debt Service'!C29 | F4: =-'Debt Service'!C30 | G4: =-'Debt Service'!C31 | I4: Senior | J4: =E4 | L4: ≈ 6.1 – 6.3 % | M4: 5 – 7 % (bancable, investment grade)
D5: 1 | E5: ='Debt Service'!D3+'Debt Service'!E3 | F5: ='Debt Service'!F3+'Debt Service'!G3 | G5: ='Debt Service'!H3+'Debt Service'!I3 | I5: Mezzanine | J5: =F4 | L5: ≈ 8.7 – 9.0 % | M5: 8 – 11 % (riesgo medio)
D6: 2 | E6: ='Debt Service'!D4+'Debt Service'!E4 | F6: ='Debt Service'!F4+'Debt Service'!G4 | G6: ='Debt Service'!H4+'Debt Service'!I4 | I6: Subordinado | J6: =G4 | L6: ≈ 11.2 – 11.5 % | M6: 10 – 14 % (riesgo alto / equity-like)
D7: 3 | E7: ='Debt Service'!D5+'Debt Service'!E5 | F7: ='Debt Service'!F5+'Debt Service'!G5 | G7: ='Debt Service'!H5+'Debt Service'!I5
D8: 4 | E8: ='Debt Service'!D6+'Debt Service'!E6 | F8: ='Debt Service'!F6+'Debt Service'!G6 | G8: ='Debt Service'!H6+'Debt Service'!I6
D9: 5 | E9: ='Debt Service'!D7+'Debt Service'!E7 | F9: ='Debt Service'!F7+'Debt Service'!G7 | G9: ='Debt Service'!H7+'Debt Service'!I7
D10: 6 | E10: ='Debt Service'!D8+'Debt Service'!E8 | F10: ='Debt Service'!F8+'Debt Service'!G8 | G10: ='Debt Service'!H8+'Debt Service'!I8 | I10: Tramo | J10: Riesgo | K10: Prioridad en waterfall | L10: TIR vs riesgo | M10: Comentario
D11: 7 | E11: ='Debt Service'!D9+'Debt Service'!E9 | F11: ='Debt Service'!F9+'Debt Service'!G9 | G11: ='Debt Service'!H9+'Debt Service'!I9 | I11: Senior | J11: Bajo | K11: Pago primero | L11: Baja volatilidad del flujo | M11: Financia 60 % de la deuda; equivalente a un bono A/BBB; óptimo para fondos de infraestructura o tokens estables colateralizados.
D12: 8 | E12: ='Debt Service'!D10+'Debt Service'!E10 | F12: ='Debt Service'!F10+'Debt Service'!G10 | G12: ='Debt Service'!H10+'Debt Service'!I10 | I12: Mezzanine | J12: Medio | K12: Pago intermedio | L12: Spread ≈ +250 bps sobre senior | M12: Cubre riesgo de flujo (años 5-12). Token con mayor yield y menor liquidez; atractivo para inversores DeFi institucionales.
D13: 9 | E13: ='Debt Service'!D11+'Debt Service'!E11 | F13: ='Debt Service'!F11+'Debt Service'!G11 | G13: ='Debt Service'!H11+'Debt Service'!I11 | I13: Subordinado | J13: Alto | K13: Último en el waterfall | L13: Alto retorno (≈ 11 %) | M13: Actúa como “bridge” entre deuda y equity; puede tokenizarse con sobrecolateralización o yield variable.
D14: 10 | E14: ='Debt Service'!D12+'Debt Service'!E12 | F14: ='Debt Service'!F12+'Debt Service'!G12 | G14: ='Debt Service'!H12+'Debt Service'!I12
D15: 11 | E15: ='Debt Service'!D13+'Debt Service'!E13 | F15: ='Debt Service'!F13+'Debt Service'!G13 | G15: ='Debt Service'!H13+'Debt Service'!I13
D16: 12 | E16: ='Debt Service'!D14+'Debt Service'!E14 | F16: ='Debt Service'!F14+'Debt Service'!G14 | G16: ='Debt Service'!H14+'Debt Service'!I14
D17: 13 | E17: ='Debt Service'!D15+'Debt Service'!E15 | F17: ='Debt Service'!F15+'Debt Service'!G15 | G17: ='Debt Service'!H15+'Debt Service'!I15
D18: 14 | E18: ='Debt Service'!D16+'Debt Service'!E16 | F18: ='Debt Service'!F16+'Debt Service'!G16 | G18: ='Debt Service'!H16+'Debt Service'!I16 | I18: Métrica | J18: Valor | K18: Comentario
D19: 15 | E19: ='Debt Service'!D17+'Debt Service'!E17 | F19: ='Debt Service'!F17+'Debt Service'!G17 | G19: ='Debt Service'!H17+'Debt Service'!I17 | I19: Base rate (SOFR) | J19: 5.0 % | K19: contexto USD 2025
I20: Spread senior | J20: =1 % | K20: → 6.0 %
D21: TIR | E21: =IRR(E4:E19) | F21: =IRR(F4:F19) | G21: =IRR(G4:G19) | I21: Spread mezzanine | J21: =3.5 % | K21: → 8.5 %
I22: Spread subordinado | J22: =6 % | K22: → 11.0 %
I23: WACD (ponderado) | J23: 7.4 % | K23: coherente con TIR ponderadas
C24: TIR_Senior ≈ 6.2 %
C25: TIR_Mezz ≈ 8.8 %
C26: TIR_Sub ≈ 11.4 % | I26: 5. Lectura estratégica (tesis / TP)
I28: Las TIRs escalonadas reflejan la eficiencia del tranching tokenizado:
I29: cada inversor puede elegir exposición y retorno según su perfil de riesgo.
I31: El spread incremental de ~250 bps por nivel está en línea con los credit spreads históricos de préstamos sindicados en infraestructuras tecnológicas.
I32: (Ver: Moody’s Project Finance Default Study, IJGlobal InfraDebt Benchmarks.)
I34: En un modelo on-chain, estos rendimientos se pueden ofrecer vía smart contracts, con cupones tokenizados (e.g. SeniorToken6, MezzToken9, SubToken11).
I37: Conclusión técnica
I38: Indicador | J38: Valor | K38: Evaluación
I39: TIR Senior | J39: 6.2 % | K39: En línea con deuda senior tradicional | M39: TIR Senior | N39: 6.2 % | O39: IRR(flows Senior) | P39: Comparable a bonos investment-grade
I40: TIR Mezz | J40: 8.8 % | K40: Compensa riesgo de subordinación media | M40: TIR Mezzanine | N40: 8.8 % | O40: IRR(flows Mezz) | P40: Riesgo medio–alto
I41: TIR Sub | J41: 11.4 % | K41: Retorno alto, similar a private debt / equity | M41: TIR Subordinado | N41: 11.4 % | O41: IRR(flows Sub) | P41: Compensa riesgo residual de subordinación
